<?xml version="1.0" encoding="UTF-8"?>
<testng-results skipped="0" failed="2" ignored="0" total="3" passed="1">
  <reporter-output>
  </reporter-output>
  <suite name="Default suite" duration-ms="1700" started-at="2019-07-21T00:44:01Z" finished-at="2019-07-21T00:44:02Z">
    <groups>
    </groups>
    <test name="Default test" duration-ms="1700" started-at="2019-07-21T00:44:01Z" finished-at="2019-07-21T00:44:02Z">
      <class name="testing.postmethod.PostMethodTests">
        <test-method status="PASS" signature="setUp()[pri:0, instance:testing.postmethod.PostMethodTests@59fa1d9b]" name="setUp" is-config="true" duration-ms="8" started-at="2019-07-21T00:44:01Z" finished-at="2019-07-21T00:44:01Z">
          <reporter-output>
          </reporter-output>
        </test-method> <!-- setUp -->
        <test-method status="PASS" signature="sendAPOSTRequestAndValidateTheResponseCode()[pri:0, instance:testing.postmethod.PostMethodTests@59fa1d9b]" name="sendAPOSTRequestAndValidateTheResponseCode" duration-ms="1251" started-at="2019-07-21T00:44:01Z" finished-at="2019-07-21T00:44:02Z">
          <reporter-output>
          </reporter-output>
        </test-method> <!-- sendAPOSTRequestAndValidateTheResponseCode -->
        <test-method status="FAIL" signature="sendAPOSTRequestForAuthenticationTest()[pri:0, instance:testing.postmethod.PostMethodTests@59fa1d9b]" name="sendAPOSTRequestForAuthenticationTest" duration-ms="209" started-at="2019-07-21T00:44:02Z" finished-at="2019-07-21T00:44:02Z">
          <exception class="java.lang.AssertionError">
            <message>
              <![CDATA[expected [401] but found [200]]]>
            </message>
            <full-stacktrace>
              <![CDATA[java.lang.AssertionError: expected [401] but found [200]
at org.testng.Assert.fail(Assert.java:96)
at org.testng.Assert.failNotEquals(Assert.java:776)
at org.testng.Assert.assertEqualsImpl(Assert.java:137)
at org.testng.Assert.assertEquals(Assert.java:118)
at org.testng.Assert.assertEquals(Assert.java:652)
at org.testng.Assert.assertEquals(Assert.java:662)
at testing.postmethod.PostMethodTests.sendAPOSTRequestForAuthenticationTest(PostMethodTests.java:139)
at sun.reflect.NativeMethodAccessorImpl.invoke0(Native Method)
at sun.reflect.NativeMethodAccessorImpl.invoke(NativeMethodAccessorImpl.java:62)
at sun.reflect.DelegatingMethodAccessorImpl.invoke(DelegatingMethodAccessorImpl.java:43)
at java.lang.reflect.Method.invoke(Method.java:498)
at org.testng.internal.MethodInvocationHelper.invokeMethod(MethodInvocationHelper.java:124)
at org.testng.internal.Invoker.invokeMethod(Invoker.java:583)
at org.testng.internal.Invoker.invokeTestMethod(Invoker.java:719)
at org.testng.internal.Invoker.invokeTestMethods(Invoker.java:989)
at org.testng.internal.TestMethodWorker.invokeTestMethods(TestMethodWorker.java:125)
at org.testng.internal.TestMethodWorker.run(TestMethodWorker.java:109)
at org.testng.TestRunner.privateRun(TestRunner.java:648)
at org.testng.TestRunner.run(TestRunner.java:505)
at org.testng.SuiteRunner.runTest(SuiteRunner.java:455)
at org.testng.SuiteRunner.runSequentially(SuiteRunner.java:450)
at org.testng.SuiteRunner.privateRun(SuiteRunner.java:415)
at org.testng.SuiteRunner.run(SuiteRunner.java:364)
at org.testng.SuiteRunnerWorker.runSuite(SuiteRunnerWorker.java:52)
at org.testng.SuiteRunnerWorker.run(SuiteRunnerWorker.java:84)
at org.testng.TestNG.runSuitesSequentially(TestNG.java:1208)
at org.testng.TestNG.runSuitesLocally(TestNG.java:1137)
at org.testng.TestNG.runSuites(TestNG.java:1049)
at org.testng.TestNG.run(TestNG.java:1017)
at org.testng.remote.AbstractRemoteTestNG.run(AbstractRemoteTestNG.java:115)
at org.testng.remote.RemoteTestNG.initAndRun(RemoteTestNG.java:251)
at org.testng.remote.RemoteTestNG.main(RemoteTestNG.java:77)
]]>
            </full-stacktrace>
          </exception> <!-- java.lang.AssertionError -->
          <reporter-output>
          </reporter-output>
        </test-method> <!-- sendAPOSTRequestForAuthenticationTest -->
        <test-method status="FAIL" signature="sendAPOSTRequestForNegativeTestAndValidateTheResponseCode()[pri:0, instance:testing.postmethod.PostMethodTests@59fa1d9b]" name="sendAPOSTRequestForNegativeTestAndValidateTheResponseCode" duration-ms="212" started-at="2019-07-21T00:44:02Z" finished-at="2019-07-21T00:44:02Z">
          <exception class="java.lang.AssertionError">
            <message>
              <![CDATA[expected [405] but found [200]]]>
            </message>
            <full-stacktrace>
              <![CDATA[java.lang.AssertionError: expected [405] but found [200]
at org.testng.Assert.fail(Assert.java:96)
at org.testng.Assert.failNotEquals(Assert.java:776)
at org.testng.Assert.assertEqualsImpl(Assert.java:137)
at org.testng.Assert.assertEquals(Assert.java:118)
at org.testng.Assert.assertEquals(Assert.java:652)
at org.testng.Assert.assertEquals(Assert.java:662)
at testing.postmethod.PostMethodTests.sendAPOSTRequestForNegativeTestAndValidateTheResponseCode(PostMethodTests.java:98)
at sun.reflect.NativeMethodAccessorImpl.invoke0(Native Method)
at sun.reflect.NativeMethodAccessorImpl.invoke(NativeMethodAccessorImpl.java:62)
at sun.reflect.DelegatingMethodAccessorImpl.invoke(DelegatingMethodAccessorImpl.java:43)
at java.lang.reflect.Method.invoke(Method.java:498)
at org.testng.internal.MethodInvocationHelper.invokeMethod(MethodInvocationHelper.java:124)
at org.testng.internal.Invoker.invokeMethod(Invoker.java:583)
at org.testng.internal.Invoker.invokeTestMethod(Invoker.java:719)
at org.testng.internal.Invoker.invokeTestMethods(Invoker.java:989)
at org.testng.internal.TestMethodWorker.invokeTestMethods(TestMethodWorker.java:125)
at org.testng.internal.TestMethodWorker.run(TestMethodWorker.java:109)
at org.testng.TestRunner.privateRun(TestRunner.java:648)
at org.testng.TestRunner.run(TestRunner.java:505)
at org.testng.SuiteRunner.runTest(SuiteRunner.java:455)
at org.testng.SuiteRunner.runSequentially(SuiteRunner.java:450)
at org.testng.SuiteRunner.privateRun(SuiteRunner.java:415)
at org.testng.SuiteRunner.run(SuiteRunner.java:364)
at org.testng.SuiteRunnerWorker.runSuite(SuiteRunnerWorker.java:52)
at org.testng.SuiteRunnerWorker.run(SuiteRunnerWorker.java:84)
at org.testng.TestNG.runSuitesSequentially(TestNG.java:1208)
at org.testng.TestNG.runSuitesLocally(TestNG.java:1137)
at org.testng.TestNG.runSuites(TestNG.java:1049)
at org.testng.TestNG.run(TestNG.java:1017)
at org.testng.remote.AbstractRemoteTestNG.run(AbstractRemoteTestNG.java:115)
at org.testng.remote.RemoteTestNG.initAndRun(RemoteTestNG.java:251)
at org.testng.remote.RemoteTestNG.main(RemoteTestNG.java:77)
]]>
            </full-stacktrace>
          </exception> <!-- java.lang.AssertionError -->
          <reporter-output>
          </reporter-output>
        </test-method> <!-- sendAPOSTRequestForNegativeTestAndValidateTheResponseCode -->
        <test-method status="PASS" signature="tearDown()[pri:0, instance:testing.postmethod.PostMethodTests@59fa1d9b]" name="tearDown" is-config="true" duration-ms="1" started-at="2019-07-21T00:44:02Z" finished-at="2019-07-21T00:44:02Z">
          <reporter-output>
          </reporter-output>
        </test-method> <!-- tearDown -->
      </class> <!-- testing.postmethod.PostMethodTests -->
    </test> <!-- Default test -->
  </suite> <!-- Default suite -->
</testng-results>
